<?xml version="1.0" encoding="UTF-8"?>
<robot xmlns:xacro="http://www.ros.org/wiki/xacro" name="robot">
  <xacro:property name="PI" value="3.1415926535897931"/>

  <!-- import gazebo reference -->
  <xacro:include filename="$(find line_rot_slam)/xacro/gazebo/robot.gazebo"/>

  <!-- base footprint -->
  <link name="base_footprint"/>

  <!-- base link -->
  <joint name="base_joint" type="fixed">
    <origin xyz="-0.1 0.0 0.15" rpy="0 0 0"/>
    <parent link="base_footprint"/>
    <child link="base_link"/>
  </joint>
  <link name="base_link">
    <visual>
      <origin xyz="0.0 0.0 0.0" rpy="0.0 0.0 0.0"/>
      <geometry>
        <box size="0.4 0.3 0.2"/>
      </geometry>
    </visual>
    <collision>
      <origin xyz="0.0 0.0 0.0" rpy="0.0 0.0 0.0"/>
      <geometry>
        <box size="0.4 0.2 0.2"/>
      </geometry>
    </collision>
    <inertial>
      <origin xyz="0.0 0.0 0.0" rpy="0.0 0.0 0.0"/>
      <mass value="5.0"/>
      <inertia ixx="0.01667" ixy="0.0" ixz="0.0" iyy="0.03333" iyz="0.0" izz="0.03333"/>
    </inertial>
  </link>

  <!-- velodyne -->
  <joint name="velodyne_joint" type="fixed">
    <origin xyz="0.1 0.0 0.2" rpy="0 0 0"/>
    <parent link="base_link"/>
    <child link="velodyne_link"/>
  </joint>
  <link name="velodyne_link">
    <visual>
      <origin xyz="0 0 0" rpy="0 0 0"/>
      <geometry>
        <box size="0.1 0.1 0.1"/>
      </geometry>
    </visual>
    <collision>
      <origin xyz="0 0 0" rpy="0 0 0"/>
      <geometry>
        <box size="0.1 0.1 0.1"/>
      </geometry>
    </collision>
    <inertial>
      <mass value="1.0"/>
      <origin xyz="0 0 0" rpy="0 0 0"/>
      <inertia ixx="0.00167" ixy="0.0" ixz="0.0" iyy="0.00167" iyz="0.0" izz="0.00167"/>
    </inertial>
  </link>

  <!-- left wheel -->
  <joint type="revolute" name="left_wheel_joint">
    <origin xyz="0.0 0.175 0.15" rpy="0.0 ${PI/2} ${PI/2}"/>
    <parent link="base_footprint"/>
    <child link="left_wheel_link"/>
    <axis xyz="0 0 1"/>
    <limit effort="100" velocity="100" lower="-5000" upper="5000"/>
  </joint>
  <link name="left_wheel_link">
    <visual name="visual">
      <origin xyz="0.0 0.0 0.0" rpy="0.0 0.0 0.0"/>
      <geometry>
        <cylinder length="0.05" radius="0.15"/>
      </geometry>
    </visual>
    <collision name="collision">
      <origin xyz="0.0 0.0 0.0" rpy="0.0 0.0 0.0"/>
      <geometry>
        <cylinder length="0.05" radius="0.15"/>
      </geometry>
    </collision>
    <inertial>
      <origin xyz="0.0 0.0 0.0" rpy="0.0 0.0 0.0"/>
      <mass value="1.0"/>
      <inertia ixx="0.00729" ixy="0.0" ixz="0.0" iyy="0.00729" iyz="0.0" izz="0.01125"/>
    </inertial>
  </link>

  <!-- right wheel -->
  <joint type="revolute" name="right_wheel_joint">
    <origin xyz="0.0 -0.175 0.15" rpy="0.0 ${PI/2} ${PI/2}"/>
    <parent link="base_footprint"/>
    <child link="right_wheel_link"/>
    <axis xyz="0 0 1"/>
    <limit effort="100" velocity="100" lower="-5000" upper="5000"/>
  </joint>
  <link name="right_wheel_link">
    <visual name="visual">
      <origin xyz="0.0 0.0 0.0" rpy="0.0 0.0 0.0"/>
      <geometry>
        <cylinder length="0.05" radius="0.15"/>
      </geometry>
    </visual>
    <collision name="collision">
      <origin xyz="0.0 0.0 0.0" rpy="0.0 0.0 0.0"/>
      <geometry>
        <cylinder length="0.05" radius="0.15"/>
      </geometry>
    </collision>
    <inertial>
      <origin xyz="0.0 0.0 0.0" rpy="0.0 0.0 0.0"/>
      <mass value="1.0"/>
      <inertia ixx="0.00729" ixy="0.0" ixz="0.0" iyy="0.00729" iyz="0.0" izz="0.01125"/>
    </inertial>
  </link>

  <!-- caster -->
  <joint name="caster_joint" type="fixed">
    <origin xyz="-0.1 0.0 -0.1" rpy="0.0 0.0 0.0"/>
    <parent link="base_link"/>
    <child link="caster_link"/>
  </joint>
  <link name="caster_link">
    <visual>
      <origin xyz="0.0 0.0 0.0" rpy="0.0 0.0 0.0"/>
      <geometry>
        <sphere radius="0.05"/>
      </geometry>
    </visual>
    <collision>
      <origin xyz="0.0 0.0 0.0" rpy="0.0 0.0 0.0"/>
      <geometry>
        <sphere radius="0.05"/>
      </geometry>
    </collision>
    <inertial>
      <origin xyz="0.0 0.0 0.0" rpy="0.0 0.0 0.0"/>
      <mass value="1.0"/>
      <inertia ixx="0.001" ixy="0.0" ixz="0.0" iyy="0.001" iyz="0.0" izz="0.001"/>
    </inertial>
  </link>
</robot>
